<?xml version="1.0" encoding="UTF-8" ?>
<testsuites errors="1"
            failures="0"
            tests="1">

  <testsuite name="test"
    errors="1" failures="0" hostname="" id="" package="test" skipped="0"
    tests="1" time="0.01700" timestamp="Thu, 23 Mar 2017 12:12:21 GMT">
  
    <testcase name="ConnectFour e2e Test" classname="test" time="0.01700" assertions="0">
    </testcase>
      <system-err>
          Error while running [Test / ConnectFour e2e Test]:

  TypeError: Cannot read property 'contains' of undefined
    at Object.ConnectFour e2e Test (/Users/WillWhitmey/ConnectFour/tests/test.js:28:32)
    at Module.call (/Users/WillWhitmey/.nvm/versions/node/v6.6.0/lib/node_modules/nightwatch/lib/runner/module.js:62:34)
    at /Users/WillWhitmey/.nvm/versions/node/v6.6.0/lib/node_modules/nightwatch/lib/runner/testcase.js:70:29
    at _fulfilled (/Users/WillWhitmey/.nvm/versions/node/v6.6.0/lib/node_modules/nightwatch/node_modules/q/q.js:834:54)
    at self.promiseDispatch.done (/Users/WillWhitmey/.nvm/versions/node/v6.6.0/lib/node_modules/nightwatch/node_modules/q/q.js:863:30)
    at Promise.promise.promiseDispatch (/Users/WillWhitmey/.nvm/versions/node/v6.6.0/lib/node_modules/nightwatch/node_modules/q/q.js:796:13)
    at /Users/WillWhitmey/.nvm/versions/node/v6.6.0/lib/node_modules/nightwatch/node_modules/q/q.js:556:49
    at runSingle (/Users/WillWhitmey/.nvm/versions/node/v6.6.0/lib/node_modules/nightwatch/node_modules/q/q.js:137:13)
    at flush (/Users/WillWhitmey/.nvm/versions/node/v6.6.0/lib/node_modules/nightwatch/node_modules/q/q.js:125:13)
    at _combinedTickCallback (internal/process/next_tick.js:67:7)
      </system-err>
  
  
  </testsuite>
</testsuites>
